<?xml version="1.0" encoding="UTF-8"?>
<testsuite name="testngTest1"
           tests="4"
           failures="1"
           errors="0"
           skipped="3"
           time="20.741">
  <properties />
            <testcase name="LoginAsBankManger" time="4.184" classname="main.java.base.BaseTest">
                <failure type="java.lang.AssertionError"
                  message="expected [0] but found [1]"
              >
<![CDATA[java.lang.AssertionError: expected [0] but found [1]
  org.testng.Assert.fail(Assert.java:97)
  org.testng.Assert.assertEqualsImpl(Assert.java:136)
  org.testng.Assert.assertEquals(Assert.java:118)
  org.testng.Assert.assertEquals(Assert.java:839)
  org.testng.Assert.assertEquals(Assert.java:849)
  main.java.base.BaseTest.LoginAsBankManger(BaseTest.java:38)
  sun.reflect.NativeMethodAccessorImpl.invoke0(Native Method)
  sun.reflect.NativeMethodAccessorImpl.invoke(NativeMethodAccessorImpl.java:62)
  sun.reflect.DelegatingMethodAccessorImpl.invoke(DelegatingMethodAccessorImpl.java:43)
  java.lang.reflect.Method.invoke(Method.java:498)
  org.testng.internal.MethodInvocationHelper.invokeMethod(MethodInvocationHelper.java:133)
  org.testng.internal.TestInvoker.invokeMethod(TestInvoker.java:584)
  org.testng.internal.TestInvoker.retryFailed(TestInvoker.java:204)
  org.testng.internal.MethodRunner.runInSequence(MethodRunner.java:58)
  org.testng.internal.TestInvoker$MethodInvocationAgent.invoke(TestInvoker.java:804)
  org.testng.internal.TestInvoker.invokeTestMethods(TestInvoker.java:145)
  org.testng.internal.TestMethodWorker.invokeTestMethods(TestMethodWorker.java:146)
  org.testng.internal.TestMethodWorker.run(TestMethodWorker.java:128)
  java.util.ArrayList.forEach(ArrayList.java:1257)
  org.testng.TestRunner.privateRun(TestRunner.java:770)
  org.testng.TestRunner.run(TestRunner.java:591)
  org.testng.SuiteRunner.runTest(SuiteRunner.java:402)
  org.testng.SuiteRunner.runSequentially(SuiteRunner.java:396)
  org.testng.SuiteRunner.privateRun(SuiteRunner.java:355)
  org.testng.SuiteRunner.run(SuiteRunner.java:304)
  org.testng.SuiteRunnerWorker.runSuite(SuiteRunnerWorker.java:53)
  org.testng.SuiteRunnerWorker.run(SuiteRunnerWorker.java:96)
  org.testng.TestNG.runSuitesSequentially(TestNG.java:1180)
  org.testng.TestNG.runSuitesLocally(TestNG.java:1102)
  org.testng.TestNG.runSuites(TestNG.java:1032)
  org.testng.TestNG.run(TestNG.java:1000)
  org.testng.IDEARemoteTestNG.run(IDEARemoteTestNG.java:73)
  org.testng.RemoteTestNGStarter.main(RemoteTestNGStarter.java:123)
]]>
      </failure>

          </testcase>
  
            <testcase name="LoginAsBankManger" time="0.0" classname="main.java.base.BaseTest">
          <skipped />
    </testcase>
            <testcase name="LoginAsBankManger" time="0.0" classname="main.java.base.BaseTest">
          <skipped />
    </testcase>
            <testcase name="LoginAsBankManger" time="0.0" classname="main.java.base.BaseTest">
          <skipped />
    </testcase>
  
  
</testsuite>
